Workbook
Name Slicer_Admission_Type: #N/A
Name Slicer_Age_Group: #N/A
Name Slicer_Country: #N/A
Name Slicer_Department: #N/A
Name Slicer_Duplicate_Test: #N/A
Name Slicer_FHIR_Status: #N/A
Name Slicer_Hospital_Name: #N/A
Name tblHospitals: Table1[#All]
Name tblHospitals: Table1[#All]
Name tblHospitals: Table1[#All]

Sheet 01_Hospitals
A1: Hospital_ID | B1: Hospital_Name | C1: Country | D1: Hospital_Type | E1: Beds | F1: EHR_System | G1: EHR_Adoption_Pct | H1: FHIR_Enabled | I1: SNOMED_CT | J1: LOINC | K1: Patient_Portal | L1: Digital_Training_Pct | M1: Digital_Gap | N1: Digital_Readiness_Level
A2: H001 | B2: Nova Medical Centre | C2: Germany | D2: University Hospital | E2: 720 | F2: MediCore Suite | G2: 0.96 | H2: Yes | I2: Yes | J2: Yes | K2: Yes | L2: 0.91 | M2: =IF(AND(Table1[[#This Row],[EHR_Adoption_Pct]]>=90%,Table1[[#This Row],[FHIR_Enabled]]<>"Yes"),"High Adoption - Interoperability Gap","No Major Gap") -> No Major Gap | N2: =IF(Table1[[#This Row],[EHR_Adoption_Pct]]>=90%,"Advanced",IF(Table1[[#This Row],[EHR_Adoption_Pct]]>=75%,"Developing","Needs Improvement")) -> Advanced
A3: H002 | B3: Aurora Medical Centre | C3: Netherland | D3: Community Hospital | E3: 460 | F3: CareLink Connect | G3: 0.93 | H3: Yes | I3: Yes | J3: Yes | K3: Yes | L3: 0.88 | M3: =IF(AND(Table1[[#This Row],[EHR_Adoption_Pct]]>=90%,Table1[[#This Row],[FHIR_Enabled]]<>"Yes"),"High Adoption - Interoperability Gap","No Major Gap") -> No Major Gap | N3: =IF(Table1[[#This Row],[EHR_Adoption_Pct]]>=90%,"Advanced",IF(Table1[[#This Row],[EHR_Adoption_Pct]]>=75%,"Developing","Needs Improvement")) -> Advanced
A4: H003 | B4: Helis General Hospital | C4: Austria | D4: General Hospital | E4: 380 | F4: MediCore Suite | G4: 0.84 | H4: Partial | I4: Partial | J4: Yes | K4: Limited | L4: 0.72 | M4: =IF(AND(Table1[[#This Row],[EHR_Adoption_Pct]]>=90%,Table1[[#This Row],[FHIR_Enabled]]<>"Yes"),"High Adoption - Interoperability Gap","No Major Gap") -> No Major Gap | N4: =IF(Table1[[#This Row],[EHR_Adoption_Pct]]>=90%,"Advanced",IF(Table1[[#This Row],[EHR_Adoption_Pct]]>=75%,"Developing","Needs Improvement")) -> Developing
A5: H004 | B5: St. Clara Medical Centre | C5: France | D5: Speciality Hospital | E5: 290 | F5: Vitalis Clinical | G5: 0.89 | H5: Yes | I5: Yes | J5: Partial | K5: Yes | L5: 0.79 | M5: =IF(AND(Table1[[#This Row],[EHR_Adoption_Pct]]>=90%,Table1[[#This Row],[FHIR_Enabled]]<>"Yes"),"High Adoption - Interoperability Gap","No Major Gap") -> No Major Gap | N5: =IF(Table1[[#This Row],[EHR_Adoption_Pct]]>=90%,"Advanced",IF(Table1[[#This Row],[EHR_Adoption_Pct]]>=75%,"Developing","Needs Improvement")) -> Developing
A6: H005 | B6: Europa Health Institute | C6: Belgium | D6: Private Multispecialty Hospital | E6: 650 | F6: NexaChart Pro | G6: 0.94 | H6: Yes | I6: Yes | J6: Yes | K6: Yes | L6: 0.86 | M6: =IF(AND(Table1[[#This Row],[EHR_Adoption_Pct]]>=90%,Table1[[#This Row],[FHIR_Enabled]]<>"Yes"),"High Adoption - Interoperability Gap","No Major Gap") -> No Major Gap | N6: =IF(Table1[[#This Row],[EHR_Adoption_Pct]]>=90%,"Advanced",IF(Table1[[#This Row],[EHR_Adoption_Pct]]>=75%,"Developing","Needs Improvement")) -> Advanced
A7: H006 | B7: Marbel General Hospital | C7: Sweden | D7: General Hospital | E7: 410 | F7: CareLink Connect | G7: 0.97 | H7: Yes | I7: Yes | J7: Yes | K7: Yes | L7: 0.93 | M7: =IF(AND(Table1[[#This Row],[EHR_Adoption_Pct]]>=90%,Table1[[#This Row],[FHIR_Enabled]]<>"Yes"),"High Adoption - Interoperability Gap","No Major Gap") -> No Major Gap | N7: =IF(Table1[[#This Row],[EHR_Adoption_Pct]]>=90%,"Advanced",IF(Table1[[#This Row],[EHR_Adoption_Pct]]>=75%,"Developing","Needs Improvement")) -> Advanced
A8: H007 | B8: Helix Medical Centre | C8: Denmark | D8: University Hospital | E8: 210 | F8: Vitalis Clinical | G8: 0.78 | H8: Partial | I8: Partial | J8: Partial | K8: Partial | L8: 0.66 | M8: =IF(AND(Table1[[#This Row],[EHR_Adoption_Pct]]>=90%,Table1[[#This Row],[FHIR_Enabled]]<>"Yes"),"High Adoption - Interoperability Gap","No Major Gap") -> No Major Gap | N8: =IF(Table1[[#This Row],[EHR_Adoption_Pct]]>=90%,"Advanced",IF(Table1[[#This Row],[EHR_Adoption_Pct]]>=75%,"Developing","Needs Improvement")) -> Developing
A9: H008 | B9: St.Aldric University Hospital | C9: Finland | D9: University Hospital | E9: 520 | F9: MediCore Suite | G9: 0.86 | H9: Yes | I9: Yes | J9: Partial | K9: Yes | L9: 0.74 | M9: =IF(AND(Table1[[#This Row],[EHR_Adoption_Pct]]>=90%,Table1[[#This Row],[FHIR_Enabled]]<>"Yes"),"High Adoption - Interoperability Gap","No Major Gap") -> No Major Gap | N9: =IF(Table1[[#This Row],[EHR_Adoption_Pct]]>=90%,"Advanced",IF(Table1[[#This Row],[EHR_Adoption_Pct]]>=75%,"Developing","Needs Improvement")) -> Developing
A10: H009 | B10: Clinica Santa Marisol | C10: Spain | D10: Community Hospital | E10: 340 | F10: Solvia HIS | G10: 0.73 | H10: Partial | I10: Partial | J10: No | K10: Limited | L10: 0.58 | M10: =IF(AND(Table1[[#This Row],[EHR_Adoption_Pct]]>=90%,Table1[[#This Row],[FHIR_Enabled]]<>"Yes"),"High Adoption - Interoperability Gap","No Major Gap") -> No Major Gap | N10: =IF(Table1[[#This Row],[EHR_Adoption_Pct]]>=90%,"Advanced",IF(Table1[[#This Row],[EHR_Adoption_Pct]]>=75%,"Developing","Needs Improvement")) -> Needs Improvement
A11: H010 | B11: Nordhavan Regional Medical Centre | C11: Italy | D11: University Hospital | E11: 180 | F11: NexaChart Pro | G11: 0.69 | H11: No | I11: No | J11: Partial | K11: No | L11: 0.51 | M11: =IF(AND(Table1[[#This Row],[EHR_Adoption_Pct]]>=90%,Table1[[#This Row],[FHIR_Enabled]]<>"Yes"),"High Adoption - Interoperability Gap","No Major Gap") -> No Major Gap | N11: =IF(Table1[[#This Row],[EHR_Adoption_Pct]]>=90%,"Advanced",IF(Table1[[#This Row],[EHR_Adoption_Pct]]>=75%,"Developing","Needs Improvement")) -> Needs Improvement
A16: Sr No. | B16: Question | C16: Result
A17: Q 1 | B17: How many hospitals are fully FHIR-enabled? | C17: =COUNTIF(Table1[[#All],[FHIR_Enabled]],H2) -> 6
A18: Q 2 | B18: What is the average EHR adoption? | C18: =AVERAGE(Table1[EHR_Adoption_Pct]) -> 0.859
A19: Q 3 | B19: What is the average digital-training percentage? | C19: =AVERAGE(Table1[Digital_Training_Pct]) -> 0.758
A20: Q 4 | B20: How many hospitals use SNOMED CT fully? | C20: =COUNTIF(Table1[[#All],[SNOMED_CT]],I2) -> 6
A22: Q 5 | B22: How many hospitals have:EHR adoption ≥90% but are not fully FHIR-enabled? | C22: {=IF(AND(Table1[[#All],[EHR_Adoption_Pct]]>=90%,Table1[[#All],[FHIR_Enabled]]<>"Yes"),"High Adoption - Interoperability Gap","No Major Gap")} -> No Major Gap

Sheet 02_ENCOUNTERS
A1: Encounter_ID | B1: Patient_ID | C1: Hospital_ID | D1: Age | E1: Age_Group | F1: Sex | G1: Department | H1: Admission_Type | I1: Admission_Date | J1: Discharge_Date | K1: LOS_Days | L1: Readmission_30D | M1: Discharge_Destination | N1: Documentation_Complete | O1: Duplicate_Test | P1: Referral_Required | Q1: Hospital_Name | R1: Country | S1: FHIR_Status
A2: E0001 | B2: P0001 | C2: H001 | D2: 34 | E2: =IF(tblEncounters[[#This Row],[Age]]<30,"18-29",IF(tblEncounters[[#This Row],[Age]]<45,"30-44",IF(tblEncounters[[#This Row],[Age]]<60,"45-59",IF(tblEncounters[[#This Row],[Age]]<75,"60-74","75+")))) -> 30-44 | F2: Female | G2: General Medicine | H2: Emergency | I2: 46074 | J2: =tblEncounters[[#This Row],[Admission_Date]]+RANDBETWEEN(1,12) -> 46085 | K2: =tblEncounters[[#This Row],[Discharge_Date]]-tblEncounters[[#This Row],[Admission_Date]] -> 11 | L2: Yes | M2: Home | N2: Yes | O2: Yes | P2: Yes | Q2: =_xlfn.XLOOKUP(tblEncounters[[#This Row],[Hospital_ID]],Table1[Hospital_ID],Table1[Hospital_Name],"Not Found") -> Nova Medical Centre | R2: =_xlfn.XLOOKUP(tblEncounters[[#This Row],[Hospital_ID]],Table1[Hospital_ID],Table1[Country],"Not Found") -> Germany | S2: =_xlfn.XLOOKUP(tblEncounters[[#This Row],[Hospital_ID]],Table1[Hospital_ID],Table1[FHIR_Enabled],"Not Found") -> Yes
A3: E0002 | B3: P0002 | C3: H002 | D3: 72 | E3: =IF(tblEncounters[[#This Row],[Age]]<30,"18-29",IF(tblEncounters[[#This Row],[Age]]<45,"30-44",IF(tblEncounters[[#This Row],[Age]]<60,"45-59",IF(tblEncounters[[#This Row],[Age]]<75,"60-74","75+")))) -> 60-74 | F3: Male | G3: Cardiology | H3: Planned | I3: 46109 | J3: =tblEncounters[[#This Row],[Admission_Date]]+RANDBETWEEN(1,12) -> 46116 | K3: =tblEncounters[[#This Row],[Discharge_Date]]-tblEncounters[[#This Row],[Admission_Date]] -> 7 | L3: No | M3: Rehabilitation | N3: Yes | O3: No | P3: No | Q3: =_xlfn.XLOOKUP(tblEncounters[[#This Row],[Hospital_ID]],Table1[Hospital_ID],Table1[Hospital_Name],"Not Found") -> Aurora Medical Centre | R3: =_xlfn.XLOOKUP(tblEncounters[[#This Row],[Hospital_ID]],Table1[Hospital_ID],Table1[Country],"Not Found") -> Netherland | S3: =_xlfn.XLOOKUP(tblEncounters[[#This Row],[Hospital_ID]],Table1[Hospital_ID],Table1[FHIR_Enabled],"Not Found") -> Yes
A4: E0003 | B4: P0003 | C4: H003 | D4: 89 | E4: =IF(tblEncounters[[#This Row],[Age]]<30,"18-29",IF(tblEncounters[[#This Row],[Age]]<45,"30-44",IF(tblEncounters[[#This Row],[Age]]<60,"45-59",IF(tblEncounters[[#This Row],[Age]]<75,"60-74","75+")))) -> 75+ | F4: Male | G4: Neurology | H4: Emergency | I4: 46035 | J4: =tblEncounters[[#This Row],[Admission_Date]]+RANDBETWEEN(1,12) -> 46036 | K4: =tblEncounters[[#This Row],[Discharge_Date]]-tblEncounters[[#This Row],[Admission_Date]] -> 1 | L4: Yes | M4: Another Hospital | N4: Yes | O4: No | P4: No | Q4: =_xlfn.XLOOKUP(tblEncounters[[#This Row],[Hospital_ID]],Table1[Hospital_ID],Table1[Hospital_Name],"Not Found") -> Helis General Hospital | R4: =_xlfn.XLOOKUP(tblEncounters[[#This Row],[Hospital_ID]],Table1[Hospital_ID],Table1[Country],"Not Found") -> Austria | S4: =_xlfn.XLOOKUP(tblEncounters[[#This Row],[Hospital_ID]],Table1[Hospital_ID],Table1[FHIR_Enabled],"Not Found") -> Partial
A5: E0004 | B5: P0004 | C5: H004 | D5: 49 | E5: =IF(tblEncounters[[#This Row],[Age]]<30,"18-29",IF(tblEncounters[[#This Row],[Age]]<45,"30-44",IF(tblEncounters[[#This Row],[Age]]<60,"45-59",IF(tblEncounters[[#This Row],[Age]]<75,"60-74","75+")))) -> 45-59 | F5: Female | G5: Orthopaedics | H5: Planned | I5: 46078 | J5: =tblEncounters[[#This Row],[Admission_Date]]+RANDBETWEEN(1,12) -> 46086 | K5: =tblEncounters[[#This Row],[Discharge_Date]]-tblEncounters[[#This Row],[Admission_Date]] -> 8 | L5: No | M5: Nursing Facility | N5: Yes | O5: No | P5: No | Q5: =_xlfn.XLOOKUP(tblEncounters[[#This Row],[Hospital_ID]],Table1[Hospital_ID],Table1[Hospital_Name],"Not Found") -> St. Clara Medical Centre | R5: =_xlfn.XLOOKUP(tblEncounters[[#This Row],[Hospital_ID]],Table1[Hospital_ID],Table1[Country],"Not Found") -> France | S5: =_xlfn.XLOOKUP(tblEncounters[[#This Row],[Hospital_ID]],Table1[Hospital_ID],Table1[FHIR_Enabled],"Not Found") -> Yes
A6: E0005 | B6: P0005 | C6: H005 | D6: 87 | E6: =IF(tblEncounters[[#This Row],[Age]]<30,"18-29",IF(tblEncounters[[#This Row],[Age]]<45,"30-44",IF(tblEncounters[[#This Row],[Age]]<60,"45-59",IF(tblEncounters[[#This Row],[Age]]<75,"60-74","75+")))) -> 75+ | F6: Male | G6: Psychiatry | H6: Emergency | I6: 46050 | J6: =tblEncounters[[#This Row],[Admission_Date]]+RANDBETWEEN(1,12) -> 46057 | K6: =tblEncounters[[#This Row],[Discharge_Date]]-tblEncounters[[#This Row],[Admission_Date]] -> 7 | L6: No | M6: Against Medical Advice | N6: Yes | O6: No | P6: Yes | Q6: =_xlfn.XLOOKUP(tblEncounters[[#This Row],[Hospital_ID]],Table1[Hospital_ID],Table1[Hospital_Name],"Not Found") -> Europa Health Institute | R6: =_xlfn.XLOOKUP(tblEncounters[[#This Row],[Hospital_ID]],Table1[Hospital_ID],Table1[Country],"Not Found") -> Belgium | S6: =_xlfn.XLOOKUP(tblEncounters[[#This Row],[Hospital_ID]],Table1[Hospital_ID],Table1[FHIR_Enabled],"Not Found") -> Yes
A7: E0006 | B7: P0006 | C7: H006 | D7: 37 | E7: =IF(tblEncounters[[#This Row],[Age]]<30,"18-29",IF(tblEncounters[[#This Row],[Age]]<45,"30-44",IF(tblEncounters[[#This Row],[Age]]<60,"45-59",IF(tblEncounters[[#This Row],[Age]]<75,"60-74","75+")))) -> 30-44 | F7: Female | G7: General Surgery | H7: Planned | I7: 46112 | J7: =tblEncounters[[#This Row],[Admission_Date]]+RANDBETWEEN(1,12) -> 46119 | K7: =tblEncounters[[#This Row],[Discharge_Date]]-tblEncounters[[#This Row],[Admission_Date]] -> 7 | L7: No | M7: Home | N7: Yes | O7: No | P7: Yes | Q7: =_xlfn.XLOOKUP(tblEncounters[[#This Row],[Hospital_ID]],Table1[Hospital_ID],Table1[Hospital_Name],"Not Found") -> Marbel General Hospital | R7: =_xlfn.XLOOKUP(tblEncounters[[#This Row],[Hospital_ID]],Table1[Hospital_ID],Table1[Country],"Not Found") -> Sweden | S7: =_xlfn.XLOOKUP(tblEncounters[[#This Row],[Hospital_ID]],Table1[Hospital_ID],Table1[FHIR_Enabled],"Not Found") -> Yes
A8: E0007 | B8: P0007 | C8: H007 | D8: 65 | E8: =IF(tblEncounters[[#This Row],[Age]]<30,"18-29",IF(tblEncounters[[#This Row],[Age]]<45,"30-44",IF(tblEncounters[[#This Row],[Age]]<60,"45-59",IF(tblEncounters[[#This Row],[Age]]<75,"60-74","75+")))) -> 60-74 | F8: Female | G8: General Medicine | H8: Emergency | I8: 46035 | J8: =tblEncounters[[#This Row],[Admission_Date]]+RANDBETWEEN(1,12) -> 46037 | K8: =tblEncounters[[#This Row],[Discharge_Date]]-tblEncounters[[#This Row],[Admission_Date]] -> 2 | L8: No | M8: Rehabilitation | N8: Yes | O8: Yes | P8: No | Q8: =_xlfn.XLOOKUP(tblEncounters[[#This Row],[Hospital_ID]],Table1[Hospital_ID],Table1[Hospital_Name],"Not Found") -> Helix Medical Centre | R8: =_xlfn.XLOOKUP(tblEncounters[[#This Row],[Hospital_ID]],Table1[Hospital_ID],Table1[Country],"Not Found") -> Denmark | S8: =_xlfn.XLOOKUP(tblEncounters[[#This Row],[Hospital_ID]],Table1[Hospital_ID],Table1[FHIR_Enabled],"Not Found") -> Partial
A9: E0008 | B9: P0008 | C9: H008 | D9: 44 | E9: =IF(tblEncounters[[#This Row],[Age]]<30,"18-29",IF(tblEncounters[[#This Row],[Age]]<45,"30-44",IF(tblEncounters[[#This Row],[Age]]<60,"45-59",IF(tblEncounters[[#This Row],[Age]]<75,"60-74","75+")))) -> 30-44 | F9: Male | G9: Cardiology | H9: Planned | I9: 46075 | J9: =tblEncounters[[#This Row],[Admission_Date]]+RANDBETWEEN(1,12) -> 46084 | K9: =tblEncounters[[#This Row],[Discharge_Date]]-tblEncounters[[#This Row],[Admission_Date]] -> 9 | L9: No | M9: Another Hospital | N9: Yes | O9: No | P9: Yes | Q9: =_xlfn.XLOOKUP(tblEncounters[[#This Row],[Hospital_ID]],Table1[Hospital_ID],Table1[Hospital_Name],"Not Found") -> St.Aldric University Hospital | R9: =_xlfn.XLOOKUP(tblEncounters[[#This Row],[Hospital_ID]],Table1[Hospital_ID],Table1[Country],"Not Found") -> Finland | S9: =_xlfn.XLOOKUP(tblEncounters[[#This Row],[Hospital_ID]],Table1[Hospital_ID],Table1[FHIR_Enabled],"Not Found") -> Yes
A10: E0009 | B10: P0009 | C10: H009 | D10: 37 | E10: =IF(tblEncounters[[#This Row],[Age]]<30,"18-29",IF(tblEncounters[[#This Row],[Age]]<45,"30-44",IF(tblEncounters[[#This Row],[Age]]<60,"45-59",IF(tblEncounters[[#This Row],[Age]]<75,"60-74","75+")))) -> 30-44 | F10: Female | G10: Neurology | H10: Emergency | I10: 46057 | J10: =tblEncounters[[#This Row],[Admission_Date]]+RANDBETWEEN(1,12) -> 46061 | K10: =tblEncounters[[#This Row],[Discharge_Date]]-tblEncounters[[#This Row],[Admission_Date]] -> 4 | L10: Yes | M10: Nursing Facility | N10: Yes | O10: No | P10: No | Q10: =_xlfn.XLOOKUP(tblEncounters[[#This Row],[Hospital_ID]],Table1[Hospital_ID],Table1[Hospital_Name],"Not Found") -> Clinica Santa Marisol | R10: =_xlfn.XLOOKUP(tblEncounters[[#This Row],[Hospital_ID]],Table1[Hospital_ID],Table1[Country],"Not Found") -> Spain | S10: =_xlfn.XLOOKUP(tblEncounters[[#This Row],[Hospital_ID]],Table1[Hospital_ID],Table1[FHIR_Enabled],"Not Found") -> Partial
A11: E0010 | B11: P0010 | C11: H010 | D11: 39 | E11: =IF(tblEncounters[[#This Row],[Age]]<30,"18-29",IF(tblEncounters[[#This Row],[Age]]<45,"30-44",IF(tblEncounters[[#This Row],[Age]]<60,"45-59",IF(tblEncounters[[#This Row],[Age]]<75,"60-74","75+")))) -> 30-44 | F11: Male | G11: Orthopaedics | H11: Emergency | I11: 46105 | J11: =tblEncounters[[#This Row],[Admission_Date]]+RANDBETWEEN(1,12) -> 46115 | K11: =tblEncounters[[#This Row],[Discharge_Date]]-tblEncounters[[#This Row],[Admission_Date]] -> 10 | L11: No | M11: Against Medical Advice | N11: No | O11: No | P11: No | Q11: =_xlfn.XLOOKUP(tblEncounters[[#This Row],[Hospital_ID]],Table1[Hospital_ID],Table1[Hospital_Name],"Not Found") -> Nordhavan Regional Medical Centre | R11: =_xlfn.XLOOKUP(tblEncounters[[#This Row],[Hospital_ID]],Table1[Hospital_ID],Table1[Country],"Not Found") -> Italy | S11: =_xlfn.XLOOKUP(tblEncounters[[#This Row],[Hospital_ID]],Table1[Hospital_ID],Table1[FHIR_Enabled],"Not Found") -> No
A12: E0011 | B12: P0011 | C12: H001 | D12: 38 | E12: =IF(tblEncounters[[#This Row],[Age]]<30,"18-29",IF(tblEncounters[[#This Row],[Age]]<45,"30-44",IF(tblEncounters[[#This Row],[Age]]<60,"45-59",IF(tblEncounters[[#This Row],[Age]]<75,"60-74","75+")))) -> 30-44 | F12: Female | G12: Psychiatry | H12: Emergency | I12: 46103 | J12: =tblEncounters[[#This Row],[Admission_Date]]+RANDBETWEEN(1,12) -> 46104 | K12: =tblEncounters[[#This Row],[Discharge_Date]]-tblEncounters[[#This Row],[Admission_Date]] -> 1 | L12: No | M12: Home | N12: Yes | O12: No | P12: Yes | Q12: =_xlfn.XLOOKUP(tblEncounters[[#This Row],[Hospital_ID]],Table1[Hospital_ID],Table1[Hospital_Name],"Not Found") -> Nova Medical Centre | R12: =_xlfn.XLOOKUP(tblEncounters[[#This Row],[Hospital_ID]],Table1[Hospital_ID],Table1[Country],"Not Found") -> Germany | S12: =_xlfn.XLOOKUP(tblEncounters[[#This Row],[Hospital_ID]],Table1[Hospital_ID],Table1[FHIR_Enabled],"Not Found") -> Yes
A13: E0012 | B13: P0012 | C13: H002 | D13: 79 | E13: =IF(tblEncounters[[#This Row],[Age]]<30,"18-29",IF(tblEncounters[[#This Row],[Age]]<45,"30-44",IF(tblEncounters[[#This Row],[Age]]<60,"45-59",IF(tblEncounters[[#This Row],[Age]]<75,"60-74","75+")))) -> 75+ | F13: Female | G13: General Surgery | H13: Emergency | I13: 46107 | J13: =tblEncounters[[#This Row],[Admission_Date]]+RANDBETWEEN(1,12) -> 46116 | K13: =tblEncounters[[#This Row],[Discharge_Date]]-tblEncounters[[#This Row],[Admission_Date]] -> 9 | L13: No | M13: Rehabilitation | N13: Yes | O13: No | P13: No | Q13: =_xlfn.XLOOKUP(tblEncounters[[#This Row],[Hospital_ID]],Table1[Hospital_ID],Table1[Hospital_Name],"Not Found") -> Aurora Medical Centre | R13: =_xlfn.XLOOKUP(tblEncounters[[#This Row],[Hospital_ID]],Table1[Hospital_ID],Table1[Country],"Not Found") -> Netherland | S13: =_xlfn.XLOOKUP(tblEncounters[[#This Row],[Hospital_ID]],Table1[Hospital_ID],Table1[FHIR_Enabled],"Not Found") -> Yes
... A51: E0050 | B51: P0050 | C51: H010 | D51: 39 | E51: =IF(tblEncounters[[#This Row],[Age]]<30,"18-29",IF(tblEncounters[[#This Row],[Age]]<45,"30-44",IF(tblEncounters[[#This Row],[Age]]<60,"45-59",IF(tblEncounters[[#This Row],[Age]]<75,"60-74","75+")))) -> 30-44 | F51: Female | G51: Cardiology | H51: Emergency | I51: 46035 | J51: =tblEncounters[[#This Row],[Admission_Date]]+RANDBETWEEN(1,12) -> 46043 | K51: =tblEncounters[[#This Row],[Discharge_Date]]-tblEncounters[[#This Row],[Admission_Date]] -> 8 | L51: No | M51: Against Medical Advice | N51: Yes | O51: No | P51: Yes | Q51: =_xlfn.XLOOKUP(tblEncounters[[#This Row],[Hospital_ID]],Table1[Hospital_ID],Table1[Hospital_Name],"Not Found") -> Nordhavan Regional Medical Centre | R51: =_xlfn.XLOOKUP(tblEncounters[[#This Row],[Hospital_ID]],Table1[Hospital_ID],Table1[Country],"Not Found") -> Italy | S51: =_xlfn.XLOOKUP(tblEncounters[[#This Row],[Hospital_ID]],Table1[Hospital_ID],Table1[FHIR_Enabled],"Not Found") -> No

Sheet 02_ENCOUNTERS_RAW
A1: Encounter_ID | B1: Patient_ID | C1: Hospital_ID | D1: Age | E1: Age_Group | F1: Sex | G1: Department | H1: Admission_Type | I1: Admission_Date | J1: Discharge_Date | K1: LOS_Days | L1: Readmission_30D | M1: Discharge_Destination | N1: Documentation_Complete | O1: Duplicate_Test | P1: Referral_Required | Q1: Hospital_Name | R1: Country | S1: FHIR_Status
A2: E0001 | B2: P0001 | C2: H001 | D2: 34 | E2: =IF(tblEncounters6[[#This Row],[Age]]<30,"18-29",IF(tblEncounters6[[#This Row],[Age]]<45,"30-44",IF(tblEncounters6[[#This Row],[Age]]<60,"45-59",IF(tblEncounters6[[#This Row],[Age]]<75,"60-74","75+")))) -> 30-44 | F2: Female | G2: General Medicine | H2: Emergency | I2: 46074 | J2: =tblEncounters6[[#This Row],[Admission_Date]]+RANDBETWEEN(1,12) -> 46081 | K2: =tblEncounters6[[#This Row],[Discharge_Date]]-tblEncounters6[[#This Row],[Admission_Date]] -> 7 | L2: Yes | M2: Home | N2: Yes | O2: Yes | P2: Yes | Q2: =_xlfn.XLOOKUP(tblEncounters6[[#This Row],[Hospital_ID]],Table1[Hospital_ID],Table1[Hospital_Name],"Not Found") -> Nova Medical Centre | R2: =_xlfn.XLOOKUP(tblEncounters6[[#This Row],[Hospital_ID]],Table1[Hospital_ID],Table1[Country],"Not Found") -> Germany | S2: =_xlfn.XLOOKUP(tblEncounters6[[#This Row],[Hospital_ID]],Table1[Hospital_ID],Table1[FHIR_Enabled],"Not Found") -> Yes
A3: E0002 | B3: P0002 | C3: H002 | D3: 72 | E3: =IF(tblEncounters6[[#This Row],[Age]]<30,"18-29",IF(tblEncounters6[[#This Row],[Age]]<45,"30-44",IF(tblEncounters6[[#This Row],[Age]]<60,"45-59",IF(tblEncounters6[[#This Row],[Age]]<75,"60-74","75+")))) -> 60-74 | F3: Male | G3: Cardiology | H3: Planned | I3: 46109 | J3: =tblEncounters6[[#This Row],[Admission_Date]]+RANDBETWEEN(1,12) -> 46117 | K3: =tblEncounters6[[#This Row],[Discharge_Date]]-tblEncounters6[[#This Row],[Admission_Date]] -> 8 | L3: No | M3: Rehabilitation | N3: Yes | O3: No | P3: No | Q3: =_xlfn.XLOOKUP(tblEncounters6[[#This Row],[Hospital_ID]],Table1[Hospital_ID],Table1[Hospital_Name],"Not Found") -> Aurora Medical Centre | R3: =_xlfn.XLOOKUP(tblEncounters6[[#This Row],[Hospital_ID]],Table1[Hospital_ID],Table1[Country],"Not Found") -> Netherland | S3: =_xlfn.XLOOKUP(tblEncounters6[[#This Row],[Hospital_ID]],Table1[Hospital_ID],Table1[FHIR_Enabled],"Not Found") -> Yes
A4: E0003 | B4: P0003 | C4: H003 | D4: 89 | E4: =IF(tblEncounters6[[#This Row],[Age]]<30,"18-29",IF(tblEncounters6[[#This Row],[Age]]<45,"30-44",IF(tblEncounters6[[#This Row],[Age]]<60,"45-59",IF(tblEncounters6[[#This Row],[Age]]<75,"60-74","75+")))) -> 75+ | F4: Male | G4: Neurology | H4: Emergency | I4: 46035 | J4: =tblEncounters6[[#This Row],[Admission_Date]]+RANDBETWEEN(1,12) -> 46040 | K4: =tblEncounters6[[#This Row],[Discharge_Date]]-tblEncounters6[[#This Row],[Admission_Date]] -> 5 | L4: Yes | M4: Another Hospital | N4: Yes | O4: No | P4: No | Q4: =_xlfn.XLOOKUP(tblEncounters6[[#This Row],[Hospital_ID]],Table1[Hospital_ID],Table1[Hospital_Name],"Not Found") -> Helis General Hospital | R4: =_xlfn.XLOOKUP(tblEncounters6[[#This Row],[Hospital_ID]],Table1[Hospital_ID],Table1[Country],"Not Found") -> Austria | S4: =_xlfn.XLOOKUP(tblEncounters6[[#This Row],[Hospital_ID]],Table1[Hospital_ID],Table1[FHIR_Enabled],"Not Found") -> Partial
A5: E0004 | B5: P0004 | C5: H004 | D5: 49 | E5: =IF(tblEncounters6[[#This Row],[Age]]<30,"18-29",IF(tblEncounters6[[#This Row],[Age]]<45,"30-44",IF(tblEncounters6[[#This Row],[Age]]<60,"45-59",IF(tblEncounters6[[#This Row],[Age]]<75,"60-74","75+")))) -> 45-59 | F5: Female | G5: Orthopaedics | H5: Planned | I5: 46078 | J5: =tblEncounters6[[#This Row],[Admission_Date]]+RANDBETWEEN(1,12) -> 46082 | K5: =tblEncounters6[[#This Row],[Discharge_Date]]-tblEncounters6[[#This Row],[Admission_Date]] -> 4 | L5: No | M5: Nursing Facility | N5: Yes | O5: No | P5: No | Q5: =_xlfn.XLOOKUP(tblEncounters6[[#This Row],[Hospital_ID]],Table1[Hospital_ID],Table1[Hospital_Name],"Not Found") -> St. Clara Medical Centre | R5: =_xlfn.XLOOKUP(tblEncounters6[[#This Row],[Hospital_ID]],Table1[Hospital_ID],Table1[Country],"Not Found") -> France | S5: =_xlfn.XLOOKUP(tblEncounters6[[#This Row],[Hospital_ID]],Table1[Hospital_ID],Table1[FHIR_Enabled],"Not Found") -> Yes
A6: E0005 | B6: P0005 | C6: H005 | D6: 87 | E6: =IF(tblEncounters6[[#This Row],[Age]]<30,"18-29",IF(tblEncounters6[[#This Row],[Age]]<45,"30-44",IF(tblEncounters6[[#This Row],[Age]]<60,"45-59",IF(tblEncounters6[[#This Row],[Age]]<75,"60-74","75+")))) -> 75+ | F6: Male | G6: Psychiatry | H6: Emergency | I6: 46050 | J6: =tblEncounters6[[#This Row],[Admission_Date]]+RANDBETWEEN(1,12) -> 46058 | K6: =tblEncounters6[[#This Row],[Discharge_Date]]-tblEncounters6[[#This Row],[Admission_Date]] -> 8 | L6: No | M6: Against Medical Advice | N6: Yes | O6: No | P6: Yes | Q6: =_xlfn.XLOOKUP(tblEncounters6[[#This Row],[Hospital_ID]],Table1[Hospital_ID],Table1[Hospital_Name],"Not Found") -> Europa Health Institute | R6: =_xlfn.XLOOKUP(tblEncounters6[[#This Row],[Hospital_ID]],Table1[Hospital_ID],Table1[Country],"Not Found") -> Belgium | S6: =_xlfn.XLOOKUP(tblEncounters6[[#This Row],[Hospital_ID]],Table1[Hospital_ID],Table1[FHIR_Enabled],"Not Found") -> Yes
A7: E0006 | B7: P0006 | C7: H006 | D7: 37 | E7: =IF(tblEncounters6[[#This Row],[Age]]<30,"18-29",IF(tblEncounters6[[#This Row],[Age]]<45,"30-44",IF(tblEncounters6[[#This Row],[Age]]<60,"45-59",IF(tblEncounters6[[#This Row],[Age]]<75,"60-74","75+")))) -> 30-44 | F7: Female | G7: General Surgery | H7: Planned | I7: 46112 | J7: =tblEncounters6[[#This Row],[Admission_Date]]+RANDBETWEEN(1,12) -> 46117 | K7: =tblEncounters6[[#This Row],[Discharge_Date]]-tblEncounters6[[#This Row],[Admission_Date]] -> 5 | L7: No | M7: Home | N7: Yes | O7: No | P7: Yes | Q7: =_xlfn.XLOOKUP(tblEncounters6[[#This Row],[Hospital_ID]],Table1[Hospital_ID],Table1[Hospital_Name],"Not Found") -> Marbel General Hospital | R7: =_xlfn.XLOOKUP(tblEncounters6[[#This Row],[Hospital_ID]],Table1[Hospital_ID],Table1[Country],"Not Found") -> Sweden | S7: =_xlfn.XLOOKUP(tblEncounters6[[#This Row],[Hospital_ID]],Table1[Hospital_ID],Table1[FHIR_Enabled],"Not Found") -> Yes
A8: E0007 | B8: P0007 | C8: H007 | D8: 65 | E8: =IF(tblEncounters6[[#This Row],[Age]]<30,"18-29",IF(tblEncounters6[[#This Row],[Age]]<45,"30-44",IF(tblEncounters6[[#This Row],[Age]]<60,"45-59",IF(tblEncounters6[[#This Row],[Age]]<75,"60-74","75+")))) -> 60-74 | F8: Female | G8: General Medicine | H8: Emergency | I8: 46035 | J8: =tblEncounters6[[#This Row],[Admission_Date]]+RANDBETWEEN(1,12) -> 46041 | K8: =tblEncounters6[[#This Row],[Discharge_Date]]-tblEncounters6[[#This Row],[Admission_Date]] -> 6 | L8: No | M8: Rehabilitation | N8: Yes | O8: Yes | P8: No | Q8: =_xlfn.XLOOKUP(tblEncounters6[[#This Row],[Hospital_ID]],Table1[Hospital_ID],Table1[Hospital_Name],"Not Found") -> Helix Medical Centre | R8: =_xlfn.XLOOKUP(tblEncounters6[[#This Row],[Hospital_ID]],Table1[Hospital_ID],Table1[Country],"Not Found") -> Denmark | S8: =_xlfn.XLOOKUP(tblEncounters6[[#This Row],[Hospital_ID]],Table1[Hospital_ID],Table1[FHIR_Enabled],"Not Found") -> Partial
A9: E0008 | B9: P0008 | C9: H008 | D9: 44 | E9: =IF(tblEncounters6[[#This Row],[Age]]<30,"18-29",IF(tblEncounters6[[#This Row],[Age]]<45,"30-44",IF(tblEncounters6[[#This Row],[Age]]<60,"45-59",IF(tblEncounters6[[#This Row],[Age]]<75,"60-74","75+")))) -> 30-44 | F9: Male | G9: Cardiology | H9: Planned | I9: 46075 | J9: =tblEncounters6[[#This Row],[Admission_Date]]+RANDBETWEEN(1,12) -> 46077 | K9: =tblEncounters6[[#This Row],[Discharge_Date]]-tblEncounters6[[#This Row],[Admission_Date]] -> 2 | L9: No | M9: Another Hospital | N9: Yes | O9: No | P9: Yes | Q9: =_xlfn.XLOOKUP(tblEncounters6[[#This Row],[Hospital_ID]],Table1[Hospital_ID],Table1[Hospital_Name],"Not Found") -> St.Aldric University Hospital | R9: =_xlfn.XLOOKUP(tblEncounters6[[#This Row],[Hospital_ID]],Table1[Hospital_ID],Table1[Country],"Not Found") -> Finland | S9: =_xlfn.XLOOKUP(tblEncounters6[[#This Row],[Hospital_ID]],Table1[Hospital_ID],Table1[FHIR_Enabled],"Not Found") -> Yes
A10: E0009 | B10: P0009 | C10: H009 | D10: 37 | E10: =IF(tblEncounters6[[#This Row],[Age]]<30,"18-29",IF(tblEncounters6[[#This Row],[Age]]<45,"30-44",IF(tblEncounters6[[#This Row],[Age]]<60,"45-59",IF(tblEncounters6[[#This Row],[Age]]<75,"60-74","75+")))) -> 30-44 | F10: Female | G10: Neurology | H10: Emergency | I10: 46057 | J10: =tblEncounters6[[#This Row],[Admission_Date]]+RANDBETWEEN(1,12) -> 46067 | K10: =tblEncounters6[[#This Row],[Discharge_Date]]-tblEncounters6[[#This Row],[Admission_Date]] -> 10 | L10: Yes | M10: Nursing Facility | N10: Yes | O10: No | P10: No | Q10: =_xlfn.XLOOKUP(tblEncounters6[[#This Row],[Hospital_ID]],Table1[Hospital_ID],Table1[Hospital_Name],"Not Found") -> Clinica Santa Marisol | R10: =_xlfn.XLOOKUP(tblEncounters6[[#This Row],[Hospital_ID]],Table1[Hospital_ID],Table1[Country],"Not Found") -> Spain | S10: =_xlfn.XLOOKUP(tblEncounters6[[#This Row],[Hospital_ID]],Table1[Hospital_ID],Table1[FHIR_Enabled],"Not Found") -> Partial
A11: E0010 | B11: P0010 | C11: H010 | D11: 39 | E11: =IF(tblEncounters6[[#This Row],[Age]]<30,"18-29",IF(tblEncounters6[[#This Row],[Age]]<45,"30-44",IF(tblEncounters6[[#This Row],[Age]]<60,"45-59",IF(tblEncounters6[[#This Row],[Age]]<75,"60-74","75+")))) -> 30-44 | F11: Male | G11: Orthopaedics | H11: Emergency | I11: 46105 | J11: =tblEncounters6[[#This Row],[Admission_Date]]+RANDBETWEEN(1,12) -> 46107 | K11: =tblEncounters6[[#This Row],[Discharge_Date]]-tblEncounters6[[#This Row],[Admission_Date]] -> 2 | L11: No | M11: Against Medical Advice | N11: No | O11: No | P11: No | Q11: =_xlfn.XLOOKUP(tblEncounters6[[#This Row],[Hospital_ID]],Table1[Hospital_ID],Table1[Hospital_Name],"Not Found") -> Nordhavan Regional Medical Centre | R11: =_xlfn.XLOOKUP(tblEncounters6[[#This Row],[Hospital_ID]],Table1[Hospital_ID],Table1[Country],"Not Found") -> Italy | S11: =_xlfn.XLOOKUP(tblEncounters6[[#This Row],[Hospital_ID]],Table1[Hospital_ID],Table1[FHIR_Enabled],"Not Found") -> No
A12: E0011 | B12: P0011 | C12: H001 | D12: 38 | E12: =IF(tblEncounters6[[#This Row],[Age]]<30,"18-29",IF(tblEncounters6[[#This Row],[Age]]<45,"30-44",IF(tblEncounters6[[#This Row],[Age]]<60,"45-59",IF(tblEncounters6[[#This Row],[Age]]<75,"60-74","75+")))) -> 30-44 | F12: Female | G12: Psychiatry | H12: Emergency | I12: 46103 | J12: =tblEncounters6[[#This Row],[Admission_Date]]+RANDBETWEEN(1,12) -> 46107 | K12: =tblEncounters6[[#This Row],[Discharge_Date]]-tblEncounters6[[#This Row],[Admission_Date]] -> 4 | L12: No | M12: Home | N12: Yes | O12: No | P12: Yes | Q12: =_xlfn.XLOOKUP(tblEncounters6[[#This Row],[Hospital_ID]],Table1[Hospital_ID],Table1[Hospital_Name],"Not Found") -> Nova Medical Centre | R12: =_xlfn.XLOOKUP(tblEncounters6[[#This Row],[Hospital_ID]],Table1[Hospital_ID],Table1[Country],"Not Found") -> Germany | S12: =_xlfn.XLOOKUP(tblEncounters6[[#This Row],[Hospital_ID]],Table1[Hospital_ID],Table1[FHIR_Enabled],"Not Found") -> Yes
A13: E0012 | B13: P0012 | C13: H002 | D13: 79 | E13: =IF(tblEncounters6[[#This Row],[Age]]<30,"18-29",IF(tblEncounters6[[#This Row],[Age]]<45,"30-44",IF(tblEncounters6[[#This Row],[Age]]<60,"45-59",IF(tblEncounters6[[#This Row],[Age]]<75,"60-74","75+")))) -> 75+ | F13: Female | G13: General Surgery | H13: Emergency | I13: 46107 | J13: =tblEncounters6[[#This Row],[Admission_Date]]+RANDBETWEEN(1,12) -> 46118 | K13: =tblEncounters6[[#This Row],[Discharge_Date]]-tblEncounters6[[#This Row],[Admission_Date]] -> 11 | L13: No | M13: Rehabilitation | N13: Yes | O13: No | P13: No | Q13: =_xlfn.XLOOKUP(tblEncounters6[[#This Row],[Hospital_ID]],Table1[Hospital_ID],Table1[Hospital_Name],"Not Found") -> Aurora Medical Centre | R13: =_xlfn.XLOOKUP(tblEncounters6[[#This Row],[Hospital_ID]],Table1[Hospital_ID],Table1[Country],"Not Found") -> Netherland | S13: =_xlfn.XLOOKUP(tblEncounters6[[#This Row],[Hospital_ID]],Table1[Hospital_ID],Table1[FHIR_Enabled],"Not Found") -> Yes
... A51: E0050 | B51: P0050 | C51: H010 | D51: 39 | E51: =IF(tblEncounters6[[#This Row],[Age]]<30,"18-29",IF(tblEncounters6[[#This Row],[Age]]<45,"30-44",IF(tblEncounters6[[#This Row],[Age]]<60,"45-59",IF(tblEncounters6[[#This Row],[Age]]<75,"60-74","75+")))) -> 30-44 | F51: Female | G51: Cardiology | H51: Emergency | I51: 46035 | J51: =tblEncounters6[[#This Row],[Admission_Date]]+RANDBETWEEN(1,12) -> 46044 | K51: =tblEncounters6[[#This Row],[Discharge_Date]]-tblEncounters6[[#This Row],[Admission_Date]] -> 9 | L51: No | M51: Against Medical Advice | N51: Yes | O51: No | P51: Yes | Q51: =_xlfn.XLOOKUP(tblEncounters6[[#This Row],[Hospital_ID]],Table1[Hospital_ID],Table1[Hospital_Name],"Not Found") -> Nordhavan Regional Medical Centre | R51: =_xlfn.XLOOKUP(tblEncounters6[[#This Row],[Hospital_ID]],Table1[Hospital_ID],Table1[Country],"Not Found") -> Italy | S51: =_xlfn.XLOOKUP(tblEncounters6[[#This Row],[Hospital_ID]],Table1[Hospital_ID],Table1[FHIR_Enabled],"Not Found") -> No

Sheet 03_ENCOUNTERS_CLEAN
A1: Encounter_ID | B1: Patient_ID | C1: Hospital_ID | D1: Age | E1: Age_Group | F1: Sex | G1: Department | H1: Admission_Type | I1: Admission_Date | J1: Discharge_Date | K1: LOS_Days | L1: Readmission_30D | M1: Discharge_Destination | N1: Documentation_Complete | O1: Duplicate_Test | P1: Referral_Required | Q1: Hospital_Name | R1: Country | S1: FHIR_Status | T1: DQ_Flag | U1: Duplicate_Encounter_Flag | V1: Department 1 | W1: Sex_Clean | X1: Admission_Type_Clean | Y1: Date_Check | Z1: Calculated_LOS | AA1: LOS_Check | AB1: Hospital_ID_Check | AC1: DQ_Issue_Type
A2: E0001 | B2: P0001 | C2: H001 | D2: 34 | E2: =IF(tblEncounters5[[#This Row],[Age]]<30,"18-29",IF(tblEncounters5[[#This Row],[Age]]<45,"30-44",IF(tblEncounters5[[#This Row],[Age]]<60,"45-59",IF(tblEncounters5[[#This Row],[Age]]<75,"60-74","75+")))) -> 30-44 | F2: Female | G2: General Medicine | H2: Emergency | I2: 46074 | J2: =tblEncounters5[[#This Row],[Admission_Date]]+RANDBETWEEN(1,12) -> 46081 | K2: =tblEncounters5[[#This Row],[Discharge_Date]]-tblEncounters5[[#This Row],[Admission_Date]] -> 7 | L2: Yes | M2: Home | N2: Yes | O2: Yes | P2: Yes | Q2: =_xlfn.XLOOKUP(tblEncounters5[[#This Row],[Hospital_ID]],Table1[Hospital_ID],Table1[Hospital_Name],"Not Found") -> Nova Medical Centre | R2: =_xlfn.XLOOKUP(tblEncounters5[[#This Row],[Hospital_ID]],Table1[Hospital_ID],Table1[Country],"Not Found") -> Germany | S2: =_xlfn.XLOOKUP(tblEncounters5[[#This Row],[Hospital_ID]],Table1[Hospital_ID],Table1[FHIR_Enabled],"Not Found") -> Yes | T2: =IF(OR(tblEncounters5[[#This Row],[Age]]="",tblEncounters5[[#This Row],[Age]]<18,tblEncounters5[[#This Row],[Age]]>100,tblEncounters5[[#This Row],[Department]]="",tblEncounters5[[#This Row],[Documentation_Complete]]="",tblEncounters5[[#This Row],[LOS_Days]]<0),"Review","OK") -> OK | U2: =IF(COUNTIF(tblEncounters5[[#All],[Encounter_ID]],tblEncounters5[[#This Row],[Encounter_ID]])>1,"Duplicate","Unique") -> Unique | V2: =PROPER(TRIM(tblEncounters5[[#This Row],[Department]])) -> General Medicine | W2: =IF(LOWER(TRIM(tblEncounters5[[#This Row],[Sex]]))="male","Male",IF(LOWER(TRIM(tblEncounters5[[#This Row],[Sex]]))="female","Female","Review")) -> Female | X2: =IF(OR(LOWER(TRIM(tblEncounters5[[#This Row],[Admission_Type]]))="emergency",LOWER(TRIM(tblEncounters5[[#This Row],[Admission_Type]]))="emerg"),"Emergency",IF(LOWER(TRIM(tblEncounters5[[#This Row],[Admission_Type]]))="planned","Planned","Review")) -> Emergency | Y2: =IF(tblEncounters5[[#This Row],[Discharge_Date]]="","Missing Discharge",IF(tblEncounters5[[#This Row],[Discharge_Date]]<tblEncounters5[[#This Row],[Admission_Date]],"Invalid Date","OK")) -> OK | Z2: =IF(OR(tblEncounters5[[#This Row],[Admission_Date]]="",tblEncounters5[[#This Row],[Discharge_Date]]=""),"",tblEncounters5[[#This Row],[Discharge_Date]]-tblEncounters5[[#This Row],[Admission_Date]]) -> 7 | AA2: =IF(tblEncounters5[[#This Row],[Calculated_LOS]]="","Missing",IF(tblEncounters5[[#This Row],[Calculated_LOS]]=tblEncounters5[[#This Row],[LOS_Days]],"Match","Mismatch")) -> Match | AB2: =IF(COUNTIF(tblEncounters[Hospital_ID],tblEncounters5[[#This Row],[Hospital_ID]])=1,"Valid","Invalid") -> Invalid | AC2: =IF(tblEncounters5[[#This Row],[Age]]="","Missing Age",IF(OR(tblEncounters5[[#This Row],[Age]]<18,tblEncounters5[[#This Row],[Age]]>100),"Invalid Age",IF(tblEncounters5[[#This Row],[Department]]="","Missing Department",IF(tblEncounters5[[#This Row],[Documentation_Complete]]="","Missing Documentation",IF(tblEncounters5[[#This Row],[LOS_Days]]<0,"Invalid LOS",IF(tblEncounters5[[#This Row],[Duplicate_Encounter_Flag]]="Duplicate","Duplicate Encounter","No Issue")))))) -> No Issue
A3: E0002 | B3: P0002 | C3: H002 | D3: 72 | E3: =IF(tblEncounters5[[#This Row],[Age]]<30,"18-29",IF(tblEncounters5[[#This Row],[Age]]<45,"30-44",IF(tblEncounters5[[#This Row],[Age]]<60,"45-59",IF(tblEncounters5[[#This Row],[Age]]<75,"60-74","75+")))) -> 60-74 | F3: Male | H3: Planned | I3: 46109 | J3: =tblEncounters5[[#This Row],[Admission_Date]]+RANDBETWEEN(1,12) -> 46117 | K3: =tblEncounters5[[#This Row],[Discharge_Date]]-tblEncounters5[[#This Row],[Admission_Date]] -> 8 | L3: No | M3: Rehabilitation | N3: Yes | O3: No | P3: No | Q3: =_xlfn.XLOOKUP(tblEncounters5[[#This Row],[Hospital_ID]],Table1[Hospital_ID],Table1[Hospital_Name],"Not Found") -> Aurora Medical Centre | R3: =_xlfn.XLOOKUP(tblEncounters5[[#This Row],[Hospital_ID]],Table1[Hospital_ID],Table1[Country],"Not Found") -> Netherland | S3: =_xlfn.XLOOKUP(tblEncounters5[[#This Row],[Hospital_ID]],Table1[Hospital_ID],Table1[FHIR_Enabled],"Not Found") -> Yes | T3: =IF(OR(tblEncounters5[[#This Row],[Age]]="",tblEncounters5[[#This Row],[Age]]<18,tblEncounters5[[#This Row],[Age]]>100,tblEncounters5[[#This Row],[Department]]="",tblEncounters5[[#This Row],[Documentation_Complete]]="",tblEncounters5[[#This Row],[LOS_Days]]<0),"Review","OK") -> Review | U3: =IF(COUNTIF(tblEncounters5[[#All],[Encounter_ID]],tblEncounters5[[#This Row],[Encounter_ID]])>1,"Duplicate","Unique") -> Unique | V3: =PROPER(TRIM(tblEncounters5[[#This Row],[Department]])) | W3: =IF(LOWER(TRIM(tblEncounters5[[#This Row],[Sex]]))="male","Male",IF(LOWER(TRIM(tblEncounters5[[#This Row],[Sex]]))="female","Female","Review")) -> Male | X3: =IF(OR(LOWER(TRIM(tblEncounters5[[#This Row],[Admission_Type]]))="emergency",LOWER(TRIM(tblEncounters5[[#This Row],[Admission_Type]]))="emerg"),"Emergency",IF(LOWER(TRIM(tblEncounters5[[#This Row],[Admission_Type]]))="planned","Planned","Review")) -> Planned | Y3: =IF(tblEncounters5[[#This Row],[Discharge_Date]]="","Missing Discharge",IF(tblEncounters5[[#This Row],[Discharge_Date]]<tblEncounters5[[#This Row],[Admission_Date]],"Invalid Date","OK")) -> OK | Z3: =IF(OR(tblEncounters5[[#This Row],[Admission_Date]]="",tblEncounters5[[#This Row],[Discharge_Date]]=""),"",tblEncounters5[[#This Row],[Discharge_Date]]-tblEncounters5[[#This Row],[Admission_Date]]) -> 8 | AA3: =IF(tblEncounters5[[#This Row],[Calculated_LOS]]="","Missing",IF(tblEncounters5[[#This Row],[Calculated_LOS]]=tblEncounters5[[#This Row],[LOS_Days]],"Match","Mismatch")) -> Match | AB3: =IF(COUNTIF(tblEncounters[Hospital_ID],tblEncounters5[[#This Row],[Hospital_ID]])=1,"Valid","Invalid") -> Invalid | AC3: =IF(tblEncounters5[[#This Row],[Age]]="","Missing Age",IF(OR(tblEncounters5[[#This Row],[Age]]<18,tblEncounters5[[#This Row],[Age]]>100),"Invalid Age",IF(tblEncounters5[[#This Row],[Department]]="","Missing Department",IF(tblEncounters5[[#This Row],[Documentation_Complete]]="","Missing Documentation",IF(tblEncounters5[[#This Row],[LOS_Days]]<0,"Invalid LOS",IF(tblEncounters5[[#This Row],[Duplicate_Encounter_Flag]]="Duplicate","Duplicate Encounter","No Issue")))))) -> Missing Department
A4: E0003 | B4: P0003 | C4: H003 | D4: 89 | E4: =IF(tblEncounters5[[#This Row],[Age]]<30,"18-29",IF(tblEncounters5[[#This Row],[Age]]<45,"30-44",IF(tblEncounters5[[#This Row],[Age]]<60,"45-59",IF(tblEncounters5[[#This Row],[Age]]<75,"60-74","75+")))) -> 75+ | F4: Male | G4: NeUrology | H4: Emergency | I4: 46035 | J4: =tblEncounters5[[#This Row],[Admission_Date]]+RANDBETWEEN(1,12) -> 46036 | K4: =tblEncounters5[[#This Row],[Discharge_Date]]-tblEncounters5[[#This Row],[Admission_Date]] -> 1 | L4: Yes | M4: Another Hospital | N4: Yes | O4: No | P4: No | Q4: =_xlfn.XLOOKUP(tblEncounters5[[#This Row],[Hospital_ID]],Table1[Hospital_ID],Table1[Hospital_Name],"Not Found") -> Helis General Hospital | R4: =_xlfn.XLOOKUP(tblEncounters5[[#This Row],[Hospital_ID]],Table1[Hospital_ID],Table1[Country],"Not Found") -> Austria | S4: =_xlfn.XLOOKUP(tblEncounters5[[#This Row],[Hospital_ID]],Table1[Hospital_ID],Table1[FHIR_Enabled],"Not Found") -> Partial | T4: =IF(OR(tblEncounters5[[#This Row],[Age]]="",tblEncounters5[[#This Row],[Age]]<18,tblEncounters5[[#This Row],[Age]]>100,tblEncounters5[[#This Row],[Department]]="",tblEncounters5[[#This Row],[Documentation_Complete]]="",tblEncounters5[[#This Row],[LOS_Days]]<0),"Review","OK") -> OK | U4: =IF(COUNTIF(tblEncounters5[[#All],[Encounter_ID]],tblEncounters5[[#This Row],[Encounter_ID]])>1,"Duplicate","Unique") -> Unique | V4: =PROPER(TRIM(tblEncounters5[[#This Row],[Department]])) -> Neurology | W4: =IF(LOWER(TRIM(tblEncounters5[[#This Row],[Sex]]))="male","Male",IF(LOWER(TRIM(tblEncounters5[[#This Row],[Sex]]))="female","Female","Review")) -> Male | X4: =IF(OR(LOWER(TRIM(tblEncounters5[[#This Row],[Admission_Type]]))="emergency",LOWER(TRIM(tblEncounters5[[#This Row],[Admission_Type]]))="emerg"),"Emergency",IF(LOWER(TRIM(tblEncounters5[[#This Row],[Admission_Type]]))="planned","Planned","Review")) -> Emergency | Y4: =IF(tblEncounters5[[#This Row],[Discharge_Date]]="","Missing Discharge",IF(tblEncounters5[[#This Row],[Discharge_Date]]<tblEncounters5[[#This Row],[Admission_Date]],"Invalid Date","OK")) -> OK | Z4: =IF(OR(tblEncounters5[[#This Row],[Admission_Date]]="",tblEncounters5[[#This Row],[Discharge_Date]]=""),"",tblEncounters5[[#This Row],[Discharge_Date]]-tblEncounters5[[#This Row],[Admission_Date]]) -> 1 | AA4: =IF(tblEncounters5[[#This Row],[Calculated_LOS]]="","Missing",IF(tblEncounters5[[#This Row],[Calculated_LOS]]=tblEncounters5[[#This Row],[LOS_Days]],"Match","Mismatch")) -> Match | AB4: =IF(COUNTIF(tblEncounters[Hospital_ID],tblEncounters5[[#This Row],[Hospital_ID]])=1,"Valid","Invalid") -> Invalid | AC4: =IF(tblEncounters5[[#This Row],[Age]]="","Missing Age",IF(OR(tblEncounters5[[#This Row],[Age]]<18,tblEncounters5[[#This Row],[Age]]>100),"Invalid Age",IF(tblEncounters5[[#This Row],[Department]]="","Missing Department",IF(tblEncounters5[[#This Row],[Documentation_Complete]]="","Missing Documentation",IF(tblEncounters5[[#This Row],[LOS_Days]]<0,"Invalid LOS",IF(tblEncounters5[[#This Row],[Duplicate_Encounter_Flag]]="Duplicate","Duplicate Encounter","No Issue")))))) -> No Issue
A5: E0004 | B5: P0004 | C5: H004 | D5: 49 | E5: =IF(tblEncounters5[[#This Row],[Age]]<30,"18-29",IF(tblEncounters5[[#This Row],[Age]]<45,"30-44",IF(tblEncounters5[[#This Row],[Age]]<60,"45-59",IF(tblEncounters5[[#This Row],[Age]]<75,"60-74","75+")))) -> 45-59 | F5: Female | G5: Orthopaedics | H5: Planned | I5: 46078 | J5: =tblEncounters5[[#This Row],[Admission_Date]]+RANDBETWEEN(1,12) -> 46089 | K5: =tblEncounters5[[#This Row],[Discharge_Date]]-tblEncounters5[[#This Row],[Admission_Date]] -> 11 | L5: No | M5: Nursing Facility | N5: Yes | O5: No | P5: No | Q5: =_xlfn.XLOOKUP(tblEncounters5[[#This Row],[Hospital_ID]],Table1[Hospital_ID],Table1[Hospital_Name],"Not Found") -> St. Clara Medical Centre | R5: =_xlfn.XLOOKUP(tblEncounters5[[#This Row],[Hospital_ID]],Table1[Hospital_ID],Table1[Country],"Not Found") -> France | S5: =_xlfn.XLOOKUP(tblEncounters5[[#This Row],[Hospital_ID]],Table1[Hospital_ID],Table1[FHIR_Enabled],"Not Found") -> Yes | T5: =IF(OR(tblEncounters5[[#This Row],[Age]]="",tblEncounters5[[#This Row],[Age]]<18,tblEncounters5[[#This Row],[Age]]>100,tblEncounters5[[#This Row],[Department]]="",tblEncounters5[[#This Row],[Documentation_Complete]]="",tblEncounters5[[#This Row],[LOS_Days]]<0),"Review","OK") -> OK | U5: =IF(COUNTIF(tblEncounters5[[#All],[Encounter_ID]],tblEncounters5[[#This Row],[Encounter_ID]])>1,"Duplicate","Unique") -> Unique | V5: =PROPER(TRIM(tblEncounters5[[#This Row],[Department]])) -> Orthopaedics | W5: =IF(LOWER(TRIM(tblEncounters5[[#This Row],[Sex]]))="male","Male",IF(LOWER(TRIM(tblEncounters5[[#This Row],[Sex]]))="female","Female","Review")) -> Female | X5: =IF(OR(LOWER(TRIM(tblEncounters5[[#This Row],[Admission_Type]]))="emergency",LOWER(TRIM(tblEncounters5[[#This Row],[Admission_Type]]))="emerg"),"Emergency",IF(LOWER(TRIM(tblEncounters5[[#This Row],[Admission_Type]]))="planned","Planned","Review")) -> Planned | Y5: =IF(tblEncounters5[[#This Row],[Discharge_Date]]="","Missing Discharge",IF(tblEncounters5[[#This Row],[Discharge_Date]]<tblEncounters5[[#This Row],[Admission_Date]],"Invalid Date","OK")) -> OK | Z5: =IF(OR(tblEncounters5[[#This Row],[Admission_Date]]="",tblEncounters5[[#This Row],[Discharge_Date]]=""),"",tblEncounters5[[#This Row],[Discharge_Date]]-tblEncounters5[[#This Row],[Admission_Date]]) -> 11 | AA5: =IF(tblEncounters5[[#This Row],[Calculated_LOS]]="","Missing",IF(tblEncounters5[[#This Row],[Calculated_LOS]]=tblEncounters5[[#This Row],[LOS_Days]],"Match","Mismatch")) -> Match | AB5: =IF(COUNTIF(tblEncounters[Hospital_ID],tblEncounters5[[#This Row],[Hospital_ID]])=1,"Valid","Invalid") -> Invalid | AC5: =IF(tblEncounters5[[#This Row],[Age]]="","Missing Age",IF(OR(tblEncounters5[[#This Row],[Age]]<18,tblEncounters5[[#This Row],[Age]]>100),"Invalid Age",IF(tblEncounters5[[#This Row],[Department]]="","Missing Department",IF(tblEncounters5[[#This Row],[Documentation_Complete]]="","Missing Documentation",IF(tblEncounters5[[#This Row],[LOS_Days]]<0,"Invalid LOS",IF(tblEncounters5[[#This Row],[Duplicate_Encounter_Flag]]="Duplicate","Duplicate Encounter","No Issue")))))) -> No Issue
A6: E0005 | B6: P0005 | C6: H005 | E6: =IF(tblEncounters5[[#This Row],[Age]]<30,"18-29",IF(tblEncounters5[[#This Row],[Age]]<45,"30-44",IF(tblEncounters5[[#This Row],[Age]]<60,"45-59",IF(tblEncounters5[[#This Row],[Age]]<75,"60-74","75+")))) -> 18-29 | F6: MALE | G6: Psychiatry | H6: Emergency | I6: 46050 | J6: =tblEncounters5[[#This Row],[Admission_Date]]+RANDBETWEEN(1,12) -> 46053 | K6: =tblEncounters5[[#This Row],[Discharge_Date]]-tblEncounters5[[#This Row],[Admission_Date]] -> 3 | L6: No | M6: Against Medical Advice | N6: Yes | O6: No | P6: Yes | Q6: =_xlfn.XLOOKUP(tblEncounters5[[#This Row],[Hospital_ID]],Table1[Hospital_ID],Table1[Hospital_Name],"Not Found") -> Europa Health Institute | R6: =_xlfn.XLOOKUP(tblEncounters5[[#This Row],[Hospital_ID]],Table1[Hospital_ID],Table1[Country],"Not Found") -> Belgium | S6: =_xlfn.XLOOKUP(tblEncounters5[[#This Row],[Hospital_ID]],Table1[Hospital_ID],Table1[FHIR_Enabled],"Not Found") -> Yes | T6: =IF(OR(tblEncounters5[[#This Row],[Age]]="",tblEncounters5[[#This Row],[Age]]<18,tblEncounters5[[#This Row],[Age]]>100,tblEncounters5[[#This Row],[Department]]="",tblEncounters5[[#This Row],[Documentation_Complete]]="",tblEncounters5[[#This Row],[LOS_Days]]<0),"Review","OK") -> Review | U6: =IF(COUNTIF(tblEncounters5[[#All],[Encounter_ID]],tblEncounters5[[#This Row],[Encounter_ID]])>1,"Duplicate","Unique") -> Unique | V6: =PROPER(TRIM(tblEncounters5[[#This Row],[Department]])) -> Psychiatry | W6: =IF(LOWER(TRIM(tblEncounters5[[#This Row],[Sex]]))="male","Male",IF(LOWER(TRIM(tblEncounters5[[#This Row],[Sex]]))="female","Female","Review")) -> Male | X6: =IF(OR(LOWER(TRIM(tblEncounters5[[#This Row],[Admission_Type]]))="emergency",LOWER(TRIM(tblEncounters5[[#This Row],[Admission_Type]]))="emerg"),"Emergency",IF(LOWER(TRIM(tblEncounters5[[#This Row],[Admission_Type]]))="planned","Planned","Review")) -> Emergency | Y6: =IF(tblEncounters5[[#This Row],[Discharge_Date]]="","Missing Discharge",IF(tblEncounters5[[#This Row],[Discharge_Date]]<tblEncounters5[[#This Row],[Admission_Date]],"Invalid Date","OK")) -> OK | Z6: =IF(OR(tblEncounters5[[#This Row],[Admission_Date]]="",tblEncounters5[[#This Row],[Discharge_Date]]=""),"",tblEncounters5[[#This Row],[Discharge_Date]]-tblEncounters5[[#This Row],[Admission_Date]]) -> 3 | AA6: =IF(tblEncounters5[[#This Row],[Calculated_LOS]]="","Missing",IF(tblEncounters5[[#This Row],[Calculated_LOS]]=tblEncounters5[[#This Row],[LOS_Days]],"Match","Mismatch")) -> Match | AB6: =IF(COUNTIF(tblEncounters[Hospital_ID],tblEncounters5[[#This Row],[Hospital_ID]])=1,"Valid","Invalid") -> Invalid | AC6: =IF(tblEncounters5[[#This Row],[Age]]="","Missing Age",IF(OR(tblEncounters5[[#This Row],[Age]]<18,tblEncounters5[[#This Row],[Age]]>100),"Invalid Age",IF(tblEncounters5[[#This Row],[Department]]="","Missing Department",IF(tblEncounters5[[#This Row],[Documentation_Complete]]="","Missing Documentation",IF(tblEncounters5[[#This Row],[LOS_Days]]<0,"Invalid LOS",IF(tblEncounters5[[#This Row],[Duplicate_Encounter_Flag]]="Duplicate","Duplicate Encounter","No Issue")))))) -> Missing Age
A7: E0006 | B7: P0006 | C7: H006 | D7: 37 | E7: =IF(tblEncounters5[[#This Row],[Age]]<30,"18-29",IF(tblEncounters5[[#This Row],[Age]]<45,"30-44",IF(tblEncounters5[[#This Row],[Age]]<60,"45-59",IF(tblEncounters5[[#This Row],[Age]]<75,"60-74","75+")))) -> 30-44 | F7: Female | G7: General Surgery | H7: Planned | I7: 46112 | J7: =tblEncounters5[[#This Row],[Admission_Date]]+RANDBETWEEN(1,12) -> 46120 | K7: =tblEncounters5[[#This Row],[Discharge_Date]]-tblEncounters5[[#This Row],[Admission_Date]] -> 8 | L7: No | M7: Home | N7: Yes | O7: No | P7: Yes | Q7: =_xlfn.XLOOKUP(tblEncounters5[[#This Row],[Hospital_ID]],Table1[Hospital_ID],Table1[Hospital_Name],"Not Found") -> Marbel General Hospital | R7: =_xlfn.XLOOKUP(tblEncounters5[[#This Row],[Hospital_ID]],Table1[Hospital_ID],Table1[Country],"Not Found") -> Sweden | S7: =_xlfn.XLOOKUP(tblEncounters5[[#This Row],[Hospital_ID]],Table1[Hospital_ID],Table1[FHIR_Enabled],"Not Found") -> Yes | T7: =IF(OR(tblEncounters5[[#This Row],[Age]]="",tblEncounters5[[#This Row],[Age]]<18,tblEncounters5[[#This Row],[Age]]>100,tblEncounters5[[#This Row],[Department]]="",tblEncounters5[[#This Row],[Documentation_Complete]]="",tblEncounters5[[#This Row],[LOS_Days]]<0),"Review","OK") -> OK | U7: =IF(COUNTIF(tblEncounters5[[#All],[Encounter_ID]],tblEncounters5[[#This Row],[Encounter_ID]])>1,"Duplicate","Unique") -> Unique | V7: =PROPER(TRIM(tblEncounters5[[#This Row],[Department]])) -> General Surgery | W7: =IF(LOWER(TRIM(tblEncounters5[[#This Row],[Sex]]))="male","Male",IF(LOWER(TRIM(tblEncounters5[[#This Row],[Sex]]))="female","Female","Review")) -> Female | X7: =IF(OR(LOWER(TRIM(tblEncounters5[[#This Row],[Admission_Type]]))="emergency",LOWER(TRIM(tblEncounters5[[#This Row],[Admission_Type]]))="emerg"),"Emergency",IF(LOWER(TRIM(tblEncounters5[[#This Row],[Admission_Type]]))="planned","Planned","Review")) -> Planned | Y7: =IF(tblEncounters5[[#This Row],[Discharge_Date]]="","Missing Discharge",IF(tblEncounters5[[#This Row],[Discharge_Date]]<tblEncounters5[[#This Row],[Admission_Date]],"Invalid Date","OK")) -> OK | Z7: =IF(OR(tblEncounters5[[#This Row],[Admission_Date]]="",tblEncounters5[[#This Row],[Discharge_Date]]=""),"",tblEncounters5[[#This Row],[Discharge_Date]]-tblEncounters5[[#This Row],[Admission_Date]]) -> 8 | AA7: =IF(tblEncounters5[[#This Row],[Calculated_LOS]]="","Missing",IF(tblEncounters5[[#This Row],[Calculated_LOS]]=tblEncounters5[[#This Row],[LOS_Days]],"Match","Mismatch")) -> Match | AB7: =IF(COUNTIF(tblEncounters[Hospital_ID],tblEncounters5[[#This Row],[Hospital_ID]])=1,"Valid","Invalid") -> Invalid | AC7: =IF(tblEncounters5[[#This Row],[Age]]="","Missing Age",IF(OR(tblEncounters5[[#This Row],[Age]]<18,tblEncounters5[[#This Row],[Age]]>100),"Invalid Age",IF(tblEncounters5[[#This Row],[Department]]="","Missing Department",IF(tblEncounters5[[#This Row],[Documentation_Complete]]="","Missing Documentation",IF(tblEncounters5[[#This Row],[LOS_Days]]<0,"Invalid LOS",IF(tblEncounters5[[#This Row],[Duplicate_Encounter_Flag]]="Duplicate","Duplicate Encounter","No Issue")))))) -> No Issue
A8: E0007 | B8: P0007 | C8: H007 | D8: 65 | E8: =IF(tblEncounters5[[#This Row],[Age]]<30,"18-29",IF(tblEncounters5[[#This Row],[Age]]<45,"30-44",IF(tblEncounters5[[#This Row],[Age]]<60,"45-59",IF(tblEncounters5[[#This Row],[Age]]<75,"60-74","75+")))) -> 60-74 | F8: Female | G8: Gen Medicine | H8: Emergency | I8: 46035 | J8: =tblEncounters5[[#This Row],[Admission_Date]]+RANDBETWEEN(1,12) -> 46043 | K8: =tblEncounters5[[#This Row],[Discharge_Date]]-tblEncounters5[[#This Row],[Admission_Date]] -> 8 | L8: No | M8: Rehabilitation | O8: Yes | P8: No | Q8: =_xlfn.XLOOKUP(tblEncounters5[[#This Row],[Hospital_ID]],Table1[Hospital_ID],Table1[Hospital_Name],"Not Found") -> Helix Medical Centre | R8: =_xlfn.XLOOKUP(tblEncounters5[[#This Row],[Hospital_ID]],Table1[Hospital_ID],Table1[Country],"Not Found") -> Denmark | S8: =_xlfn.XLOOKUP(tblEncounters5[[#This Row],[Hospital_ID]],Table1[Hospital_ID],Table1[FHIR_Enabled],"Not Found") -> Partial | T8: =IF(OR(tblEncounters5[[#This Row],[Age]]="",tblEncounters5[[#This Row],[Age]]<18,tblEncounters5[[#This Row],[Age]]>100,tblEncounters5[[#This Row],[Department]]="",tblEncounters5[[#This Row],[Documentation_Complete]]="",tblEncounters5[[#This Row],[LOS_Days]]<0),"Review","OK") -> Review | U8: =IF(COUNTIF(tblEncounters5[[#All],[Encounter_ID]],tblEncounters5[[#This Row],[Encounter_ID]])>1,"Duplicate","Unique") -> Unique | V8: =PROPER(TRIM(tblEncounters5[[#This Row],[Department]])) -> Gen Medicine | W8: =IF(LOWER(TRIM(tblEncounters5[[#This Row],[Sex]]))="male","Male",IF(LOWER(TRIM(tblEncounters5[[#This Row],[Sex]]))="female","Female","Review")) -> Female | X8: =IF(OR(LOWER(TRIM(tblEncounters5[[#This Row],[Admission_Type]]))="emergency",LOWER(TRIM(tblEncounters5[[#This Row],[Admission_Type]]))="emerg"),"Emergency",IF(LOWER(TRIM(tblEncounters5[[#This Row],[Admission_Type]]))="planned","Planned","Review")) -> Emergency | Y8: =IF(tblEncounters5[[#This Row],[Discharge_Date]]="","Missing Discharge",IF(tblEncounters5[[#This Row],[Discharge_Date]]<tblEncounters5[[#This Row],[Admission_Date]],"Invalid Date","OK")) -> OK | Z8: =IF(OR(tblEncounters5[[#This Row],[Admission_Date]]="",tblEncounters5[[#This Row],[Discharge_Date]]=""),"",tblEncounters5[[#This Row],[Discharge_Date]]-tblEncounters5[[#This Row],[Admission_Date]]) -> 8 | AA8: =IF(tblEncounters5[[#This Row],[Calculated_LOS]]="","Missing",IF(tblEncounters5[[#This Row],[Calculated_LOS]]=tblEncounters5[[#This Row],[LOS_Days]],"Match","Mismatch")) -> Match | AB8: =IF(COUNTIF(tblEncounters[Hospital_ID],tblEncounters5[[#This Row],[Hospital_ID]])=1,"Valid","Invalid") -> Invalid | AC8: =IF(tblEncounters5[[#This Row],[Age]]="","Missing Age",IF(OR(tblEncounters5[[#This Row],[Age]]<18,tblEncounters5[[#This Row],[Age]]>100),"Invalid Age",IF(tblEncounters5[[#This Row],[Department]]="","Missing Department",IF(tblEncounters5[[#This Row],[Documentation_Complete]]="","Missing Documentation",IF(tblEncounters5[[#This Row],[LOS_Days]]<0,"Invalid LOS",IF(tblEncounters5[[#This Row],[Duplicate_Encounter_Flag]]="Duplicate","Duplicate Encounter","No Issue")))))) -> Missing Documentation
A9: E0008 | B9: P0008 | C9: H008 | D9: 44 | E9: =IF(tblEncounters5[[#This Row],[Age]]<30,"18-29",IF(tblEncounters5[[#This Row],[Age]]<45,"30-44",IF(tblEncounters5[[#This Row],[Age]]<60,"45-59",IF(tblEncounters5[[#This Row],[Age]]<75,"60-74","75+")))) -> 30-44 | F9: Male | G9: Cardiology | H9: Planned | I9: 46075 | J9: =tblEncounters5[[#This Row],[Admission_Date]]+RANDBETWEEN(1,12) -> 46080 | K9: =tblEncounters5[[#This Row],[Discharge_Date]]-tblEncounters5[[#This Row],[Admission_Date]] -> 5 | L9: No | M9: Another Hospital | N9: Yes | O9: No | P9: Yes | Q9: =_xlfn.XLOOKUP(tblEncounters5[[#This Row],[Hospital_ID]],Table1[Hospital_ID],Table1[Hospital_Name],"Not Found") -> St.Aldric University Hospital | R9: =_xlfn.XLOOKUP(tblEncounters5[[#This Row],[Hospital_ID]],Table1[Hospital_ID],Table1[Country],"Not Found") -> Finland | S9: =_xlfn.XLOOKUP(tblEncounters5[[#This Row],[Hospital_ID]],Table1[Hospital_ID],Table1[FHIR_Enabled],"Not Found") -> Yes | T9: =IF(OR(tblEncounters5[[#This Row],[Age]]="",tblEncounters5[[#This Row],[Age]]<18,tblEncounters5[[#This Row],[Age]]>100,tblEncounters5[[#This Row],[Department]]="",tblEncounters5[[#This Row],[Documentation_Complete]]="",tblEncounters5[[#This Row],[LOS_Days]]<0),"Review","OK") -> OK | U9: =IF(COUNTIF(tblEncounters5[[#All],[Encounter_ID]],tblEncounters5[[#This Row],[Encounter_ID]])>1,"Duplicate","Unique") -> Unique | V9: =PROPER(TRIM(tblEncounters5[[#This Row],[Department]])) -> Cardiology | W9: =IF(LOWER(TRIM(tblEncounters5[[#This Row],[Sex]]))="male","Male",IF(LOWER(TRIM(tblEncounters5[[#This Row],[Sex]]))="female","Female","Review")) -> Male | X9: =IF(OR(LOWER(TRIM(tblEncounters5[[#This Row],[Admission_Type]]))="emergency",LOWER(TRIM(tblEncounters5[[#This Row],[Admission_Type]]))="emerg"),"Emergency",IF(LOWER(TRIM(tblEncounters5[[#This Row],[Admission_Type]]))="planned","Planned","Review")) -> Planned | Y9: =IF(tblEncounters5[[#This Row],[Discharge_Date]]="","Missing Discharge",IF(tblEncounters5[[#This Row],[Discharge_Date]]<tblEncounters5[[#This Row],[Admission_Date]],"Invalid Date","OK")) -> OK | Z9: =IF(OR(tblEncounters5[[#This Row],[Admission_Date]]="",tblEncounters5[[#This Row],[Discharge_Date]]=""),"",tblEncounters5[[#This Row],[Discharge_Date]]-tblEncounters5[[#This Row],[Admission_Date]]) -> 5 | AA9: =IF(tblEncounters5[[#This Row],[Calculated_LOS]]="","Missing",IF(tblEncounters5[[#This Row],[Calculated_LOS]]=tblEncounters5[[#This Row],[LOS_Days]],"Match","Mismatch")) -> Match | AB9: =IF(COUNTIF(tblEncounters[Hospital_ID],tblEncounters5[[#This Row],[Hospital_ID]])=1,"Valid","Invalid") -> Invalid | AC9: =IF(tblEncounters5[[#This Row],[Age]]="","Missing Age",IF(OR(tblEncounters5[[#This Row],[Age]]<18,tblEncounters5[[#This Row],[Age]]>100),"Invalid Age",IF(tblEncounters5[[#This Row],[Department]]="","Missing Department",IF(tblEncounters5[[#This Row],[Documentation_Complete]]="","Missing Documentation",IF(tblEncounters5[[#This Row],[LOS_Days]]<0,"Invalid LOS",IF(tblEncounters5[[#This Row],[Duplicate_Encounter_Flag]]="Duplicate","Duplicate Encounter","No Issue")))))) -> No Issue
